#VRML_SIM R2021a utf8
WorldInfo {
}
Viewpoint {
  fieldOfView 1.0472
  orientation 0.16634609376376236 -0.41962395251824103 -0.8923254538353742 2.296829252417245
  position -1.4519284840340148 1.1558768649537374 1.8753825892200024
}
Solid {
  rotation 1 0 0 1.57079632679
  children [
    Shape {
      appearance PBRAppearance {
        baseColor 0.45 0.15 0.15
        roughness 1
        metalness 0
        IBLStrength 0
        emissiveIntensity 0
      }
      geometry Plane {
        size 5 5
      }
    }
  ]
  name "Floor"
  boundingObject Plane {
    size 5 5
  }
  locked TRUE
}
Background {
  skyColor [
    0.15 0.45 1
  ]
}
DirectionalLight {
  castShadows TRUE
}
DEF RobotTemplate Robot {
  translation 2.8443388164002488e-12 -1.8367728249428692e-08 -0.013902311876438977
  rotation 0.999999980902263 0.00015048523489597006 0.00012469830581189045 -5.299786968462981e-06
  children [
    Transform {
      translation 0 0 0.8128
      children [
        Shape {
          appearance PBRAppearance {
            metalness 0
          }
          geometry Box {
            size 0.7112 0.9652 1.524
          }
        }
      ]
    }
    HingeJoint {
      jointParameters HingeJointParameters {
        position 3.430894836904035e-07
        anchor -0.3683 0.35 0.0762
      }
      device [
        PositionSensor {
          name "CAN1 #"
        }
        RotationalMotor {
          name "Motor1 # front left"
          maxVelocity 50
        }
      ]
      endPoint RobotWheel {
        translation -0.3683 0.3498160000797259 0.07973370000415134
        name "FL Wheel"
      }
    }
    HingeJoint {
      jointParameters HingeJointParameters {
        position 1.2266253874234143e-08
        anchor 0.3683 0.35 0.0761856
      }
      device [
        PositionSensor {
          name "CAN2 #"
        }
        RotationalMotor {
          name "Motor2 # front right"
          maxVelocity 50
        }
      ]
      endPoint RobotWheel {
        translation 0.3683 0.35001199999477145 0.0797337000000177
        name "FR Wheel"
      }
    }
    HingeJoint {
      jointParameters HingeJointParameters {
        position -8.75277265951556e-11
        anchor -0.3683 -0.35 0.0761856
      }
      device [
        PositionSensor {
          name "CAN3 #"
        }
        RotationalMotor {
          name "Motor3 # back left"
          maxVelocity 50
        }
      ]
      endPoint RobotWheel {
        translation -0.3683 -0.34999999999811965 0.0797325
        rotation 0.4043832870637698 -0.9145896100415567 4.845135987322454e-05 9.86749687334645e-13
        name "BL wheel"
      }
    }
    HingeJoint {
      jointParameters HingeJointParameters {
        position 4.387069634291414e-09
        anchor 0.3683 -0.35 0.0761856
      }
      device [
        PositionSensor {
          name "CAN4 #"
        }
        RotationalMotor {
          name "Motor4 # back right"
          maxVelocity 50
        }
      ]
      endPoint RobotWheel {
        translation 0.3683 -0.3499880000052254 0.07973250000001766
        name "BR wheel"
      }
    }
    DistanceSensor {
      translation 0.3683 0 0.1
      children [
        Shape {
          appearance PBRAppearance {
            baseColor 1 0 0
            metalness 0
          }
          geometry Box {
            size 0.0254 0.05 0.05
          }
        }
      ]
      name "Analog1"
      lookupTable [
        0 0 0
        100 100 0
      ]
    }
    DistanceSensor {
      translation 0 0.4953 0.1
      rotation 0 0 -1 -1.5708
      children [
        Shape {
          appearance PBRAppearance {
            baseColor 0 0 1
            metalness 0
          }
          geometry Box {
            size 0.0254 0.05 0.05
          }
        }
      ]
      name "Analog2"
      lookupTable [
        0 0 0
        100 100 0
      ]
    }
  ]
  name "basic robot"
  boundingObject Transform {
    translation 0 0 0.8128
    children [
      Shape {
        appearance PBRAppearance {
          metalness 0
        }
        geometry Box {
          size 0.7112 0.9652 1.524
        }
      }
    ]
  }
  physics Physics {
    density -1
    mass 50
  }
  controller "http_robot"
  linearVelocity -2.1749668032670013e-12 2.2147378370645768e-09 -5.139722393839786e-06
  angularVelocity -2.7444043959346537e-09 -2.6796000377586693e-12 1.5725153909892648e-13
}
