#VRML_SIM R2021a utf8
WorldInfo {
}
Viewpoint {
  fieldOfView 1.0472
  orientation 0.16634609376376236 -0.41962395251824103 -0.8923254538353742 2.296829252417245
  position -1.4519284840340148 1.1558768649537374 1.8753825892200024
}
Solid {
  rotation 1 0 0 1.57079632679
  children [
    Shape {
      appearance PBRAppearance {
        baseColor 0.45 0.15 0.15
        roughness 1
        metalness 0
        IBLStrength 0
        emissiveIntensity 0
      }
      geometry Plane {
        size 5 5
      }
    }
  ]
  name "Floor"
  boundingObject Plane {
    size 5 5
  }
  locked TRUE
}
Background {
  skyColor [
    0.15 0.45 1
  ]
}
DirectionalLight {
  castShadows TRUE
}
DEF RobotTemplate Robot {
  children [
    Transform {
      translation 0 0 0.8128
      children [
        Shape {
          appearance PBRAppearance {
            metalness 0
          }
          geometry Box {
            size 0.7112 0.9652 1.524
          }
        }
      ]
    }
    HingeJoint {
      jointParameters HingeJointParameters {
        position 3.656510691791486e-07
        anchor -0.3683 0.35 0.0762
      }
      device [
        RotationalMotor {
          name "Motor1 # front left"
          maxVelocity 50
        }
      ]
      endPoint RobotWheel {
        translation -0.3683 0.349816 0.0797337
        name "FL Wheel"
      }
    }
    HingeJoint {
      jointParameters HingeJointParameters {
        position 1.0792643952862534e-08
        anchor 0.3683 0.35 0.0761856
      }
      device [
        RotationalMotor {
          name "Motor2 # front right"
          maxVelocity 50
        }
      ]
      endPoint RobotWheel {
        translation 0.3683 0.350012 0.0797337
        name "FR Wheel"
      }
    }
    HingeJoint {
      jointParameters HingeJointParameters {
        position -8.85145029509448e-11
        anchor -0.3683 -0.35 0.0761856
      }
      device [
        RotationalMotor {
          name "Motor3 # back left"
          maxVelocity 50
        }
      ]
      endPoint RobotWheel {
        translation -0.3683 -0.3499999999984301 0.0797325
        name "BL wheel"
      }
    }
    HingeJoint {
      jointParameters HingeJointParameters {
        position 2.913842280909397e-09
        anchor 0.3683 -0.35 0.0761856
      }
      device [
        RotationalMotor {
          name "Motor4 # back right"
          maxVelocity 50
        }
      ]
      endPoint RobotWheel {
        translation 0.3683 -0.349988 0.0797325
        name "BR wheel"
      }
    }
    DistanceSensor {
      translation 0.3683 0 0.1
      children [
        Shape {
          appearance PBRAppearance {
            baseColor 1 0 0
            metalness 0
          }
          geometry Box {
            size 0.0254 0.05 0.05
          }
        }
      ]
      name "Analog1"
      lookupTable [
        0 0 0
        100 100 0
      ]
    }
    DistanceSensor {
      translation 0 0.4953 0.1
      rotation 0 0 -1 -1.5708
      children [
        Shape {
          appearance PBRAppearance {
            baseColor 0 0 1
            metalness 0
          }
          geometry Box {
            size 0.0254 0.05 0.05
          }
        }
      ]
      name "Analog2"
      lookupTable [
        0 0 0
        100 100 0
      ]
    }
  ]
  name "basic robot"
  boundingObject Transform {
    translation 0 0 0.8128
    children [
      Shape {
        appearance PBRAppearance {
          metalness 0
        }
        geometry Box {
          size 0.7112 0.9652 1.524
        }
      }
    ]
  }
  physics Physics {
    density -1
    mass 50
  }
  controller "http_robot"
}
